<?xml version="1.0"?>
<robot name="amr_crick">

    <gazebo>
        <plugin name="gazebo_ros_control" filename="libgazebo_ros_control.so">
            <robotNamespace>/amr_crick</robotNamespace>
        </plugin>
    </gazebo>

    <material name="green">
        <color rgba="0 0.8 0 1"/>
    </material>

    <material name="red">
        <color rgba="1 0 0 1"/>
    </material>

    <!-- base_link START -->
    <link name="base_link">

        <inertial>
            <origin xyz="0 0 0" rpy="0 0 0"/>
            <mass value="0.3" />
            <inertia ixx="6.7e-11" ixy="0.0" ixz="0.0" iyy="1.3e-10" iyz="0.0" izz="8.4e-11"/>
        </inertial>
        
        <collision>
            <origin xyz="0 0 0" rpy="0 0 0"/>
            <geometry>
                <mesh filename="package://amr_crick_description/models/meshes/amr_crick_mozzo_caster.dae"/>
            </geometry>
        </collision>

        <visual>
            <origin rpy="1.5708 0 0" xyz="0 0 0"/>
            <geometry>
                <mesh filename="package://amr_crick_description/models/meshes/amr_crick_mozzo_caster.dae"/>
            </geometry>
            <material name="green"/>
        </visual>

    </link>


    <gazebo reference="base_link">
        <kp>1000.0</kp>
        <kd>1000.0</kd>
        <mu1>10.0</mu1>
        <mu2>10.0</mu2>
        <material>Gazebo/Grey</material>
    </gazebo>

    <!-- base_link END -->


    <!-- rods_sx_down_link START -->

    <link name="rods_sx_down_link">

        <inertial>
            <origin xyz="0 0 0" rpy="0 0 0"/>
            <mass value="0.089" />
            <inertia ixx="1.42e-10" ixy="0.0" ixz="0.0" iyy="2.16e-10" iyz="0.0" izz="7.5e-11"/>
        </inertial>
        
        <collision>
            <origin xyz="0 0 0" rpy="0 0 0"/>
            <geometry>
                <mesh filename="package://amr_crick_description/models/meshes/amr_crick_rods_sx_down.dae"/>
            </geometry>
        </collision> 

        <visual>
            <origin rpy="1.5708 0 0" xyz="0 0 0"/>
            <geometry>
                <mesh filename="package://amr_crick_description/models/meshes/amr_crick_rods_sx_down.dae"/>
            </geometry>
             <material name="red"/>
        </visual>
    </link>

    <gazebo reference="rods_sx_down_link">
        <kp>1000.0</kp>
        <kd>1000.0</kd>
        <mu1>10.0</mu1>
        <mu2>10.0</mu2>
        <material>Gazebo/Grey</material>
    </gazebo>

    <!-- rods_sx_down_link END -->

    <!-- 1/ roll_down_rods_sx_down_joint START -->        
    <joint name="roll_down_rods_sx_down_joint" type="revolute">
        <parent link="base_link"/>
        <child link="rods_sx_down_link"/>
        <origin xyz="0.0 -0.017 -0.004" rpy="-0.24 0 0"/>
        <limit lower="-3.14159" upper="3.14159" effort="100" velocity="0.005"/>
        <axis xyz="1 0 0"/>
    </joint>

    <transmission name="tran1">
        <type>transmission_interface/SimpleTransmission</type>
        <joint name="roll_down_rods_sx_down_joint">
            <hardwareInterface>EffortJointInterface</hardwareInterface>
        </joint>
        <actuator name="motor1">
            <hardwareInterface>EffortJointInterface</hardwareInterface>
            <mechanicalReduction>1</mechanicalReduction>
        </actuator>
    </transmission>
    <!-- roll_down_rods_sx_down_joint END -->   

    <!-- amr_crick_mozzo_motore_link START -->

    <link name="amr_crick_mozzo_motore_link">

        <inertial>
            <origin xyz="0 0 0" rpy="0 0 0"/>
            <mass value="0.47" />
            <inertia ixx="2e-10" ixy="0.0" ixz="0.0" iyy="2.37e-10" iyz="0.0" izz="1.68e-10"/>
        </inertial>
        
        <collision>
            <origin xyz="0 0 0" rpy="0 0 0"/>
            <geometry>
                <mesh filename="package://amr_crick_description/models/meshes/amr_crick_mozzo_motore.dae"/>
            </geometry> 
        </collision>  

        <visual>
            <origin rpy="1.5708 0 0" xyz="0 0 0"/>
            <geometry>
                <mesh filename="package://amr_crick_description/models/meshes/amr_crick_mozzo_motore.dae"/>
            </geometry>
             <material name="red"/>
        </visual>
    </link>

    <gazebo reference="amr_crick_mozzo_motore_link">
        <kp>1000.0</kp>
        <kd>1000.0</kd>
        <mu1>10</mu1>
        <mu2>10</mu2>
        <material>Gazebo/Grey</material>
    </gazebo>

    <!-- amr_crick_mozzo_motore_link END -->

    <!-- 2/ roll_up_rods_sx_down_joint START -->        
    <joint name="roll_up_rods_sx_down_joint" type="revolute">
        <parent link="rods_sx_down_link"/>
        <child link="amr_crick_mozzo_motore_link"/>
        <origin xyz="0.0 -0.078 0" rpy="0.24 0 0"/>
        <limit lower="-3.14159" upper="3.14159" effort="100" velocity="0.005"/>
        <axis xyz="1 0 0"/>
    </joint>

    <transmission name="tran2">
        <type>transmission_interface/SimpleTransmission</type>
        <joint name="roll_up_rods_sx_down_joint">
            <hardwareInterface>EffortJointInterface</hardwareInterface>
        </joint>
        <actuator name="motor2">
            <hardwareInterface>EffortJointInterface</hardwareInterface>
            <mechanicalReduction>1</mechanicalReduction>
        </actuator>
    </transmission>
    <!-- roll_down_rods_sx_down_joint END --> 

    <!-- rods_sx_up_link START -->

    <link name="rods_sx_up_link">

        <inertial>
            <origin xyz="0 0 0" rpy="0 0 0"/>
            <mass value="0.089" />
            <inertia ixx="3e-10" ixy="0.0" ixz="0.0" iyy="3.8e-10" iyz="0.0" izz="7.5e-11"/>
        </inertial>
        
        <collision>
            <origin xyz="0 0 0" rpy="0 0 0"/>
            <geometry>
                <mesh filename="package://amr_crick_description/models/meshes/amr_crick_rods_sx_up.dae"/>
            </geometry>
        </collision> 

        <visual>
            <origin rpy="1.5708 0 0" xyz="0 0 0"/>
            <geometry>
                <mesh filename="package://amr_crick_description/models/meshes/amr_crick_rods_sx_up.dae"/>
            </geometry>
             <material name="red"/>
        </visual>
    </link>

    <gazebo reference="rods_sx_up_link">
        <kp>1000.0</kp>
        <kd>1000.0</kd>
        <mu1>10</mu1>
        <mu2>10</mu2>
        <material>Gazebo/Grey</material>
    </gazebo>

    <!-- rods_sx_up_link END -->

    <!-- 3/ roll_down_rods_sx_up_joint START -->        
    <joint name="roll_down_rods_sx_up_joint" type="revolute">
        <parent link="amr_crick_mozzo_motore_link"/>
        <child link="rods_sx_up_link"/>
        <origin xyz="0 0 0" rpy="3.38159 0 0"/>
        <limit lower="-3.14159" upper="3.14159" effort="1000" velocity="0.005"/>
        <axis xyz="1 0 0"/>
    </joint>

    <transmission name="tran3">
        <type>transmission_interface/SimpleTransmission</type>
        <joint name="roll_down_rods_sx_up_joint">
            <hardwareInterface>EffortJointInterface</hardwareInterface>
        </joint>
        <actuator name="motor3">
            <hardwareInterface>EffortJointInterface</hardwareInterface>
            <mechanicalReduction>1</mechanicalReduction>
        </actuator>
    </transmission>
    <!-- roll_down_rods_sx_up_joint END --> 

    <!-- amr_crick_appoggio_link START -->

    <link name="amr_crick_appoggio_link">

        <inertial>
            <origin xyz="0 0 0" rpy="0 0 0"/>
            <mass value="0.33" />
            <inertia ixx="6.3e-11" ixy="0.0" ixz="0.0" iyy="2.33e-10" iyz="0.0" izz="1.79e-10"/>
        </inertial>
       
        <collision>
            <origin xyz="0 0 0" rpy="0 0 0"/>
            <geometry>
                <mesh filename="package://amr_crick_description/models/meshes/amr_crick_appoggio.dae"/>
            </geometry>
        </collision> 

        <visual>
            <origin rpy="1.5708 0 0" xyz="0 -0.017 0"/>
            <geometry>
                <mesh filename="package://amr_crick_description/models/meshes/amr_crick_appoggio.dae"/>
            </geometry>
             <material name="red"/>
        </visual>
    </link>

    <gazebo reference="amr_crick_appoggio_link">
        <kp>1000.0</kp>
        <kd>1000.0</kd>
        <mu1>10</mu1>
        <mu2>10</mu2>
        <material>Gazebo/Grey</material>
    </gazebo>

    <!-- mr_crick_appoggio_link END -->

    <!-- 4/ roll_up_rods_sx_up_joint START -->        
    <joint name="roll_up_rods_sx_up_joint" type="revolute">
        <parent link="rods_sx_up_link"/>
        <child link="amr_crick_appoggio_link"/>
        <origin xyz="0 -0.078 0" rpy="-0.24 0 0"/>
        <limit lower="-3.14159" upper="3.14159" effort="1000" velocity="0.005"/>
        <axis xyz="1 0 0"/>
    </joint>

    <transmission name="tran4">
        <type>transmission_interface/SimpleTransmission</type>
        <joint name="roll_up_rods_sx_up_joint">
            <hardwareInterface>EffortJointInterface</hardwareInterface>
        </joint>
        <actuator name="motor4">
            <hardwareInterface>EffortJointInterface</hardwareInterface>
            <mechanicalReduction>1</mechanicalReduction>
        </actuator>
    </transmission>

    <!-- roll_up_rods_sx_up_joint END --> 

    <!-- rods_dx_up_link START -->

    <link name="rods_dx_up_link">

        <inertial>
            <origin xyz="0 0 0" rpy="0 0 0"/>
            <mass value="0.089" />
            <inertia ixx="3e-10" ixy="0.0" ixz="0.0" iyy="3.8e-10" iyz="0.0" izz="7.5e-11"/>
        </inertial>
       
        <collision>
            <origin xyz="0 0 0" rpy="0 0 0"/>
            <geometry>
                <mesh filename="package://amr_crick_description/models/meshes/amr_crick_rods_sx_up.dae"/>
            </geometry>
        </collision>

        <visual>
            <origin rpy="1.5708 0 0" xyz="0 0 0"/>
            <geometry>
                <mesh filename="package://amr_crick_description/models/meshes/amr_crick_rods_sx_up.dae"/>
            </geometry>
             <material name="red"/>
        </visual>
    </link>

    <gazebo reference="rods_dx_up_link">
        <kp>1000.0</kp>
        <kd>1000.0</kd>
        <mu1>10</mu1>
        <mu2>10</mu2>
        <material>Gazebo/Grey</material>
    </gazebo>

    <!-- rods_dx_up_link END -->

    <!-- 5/ roll_up_rods_dx_up_joint START -->        
    <joint name="roll_up_rods_dx_up_joint" type="revolute">
        <parent link="amr_crick_appoggio_link"/>
        <child link="rods_dx_up_link"/>
        <origin xyz="0 -0.034 0" rpy="-0.24 0 0"/>
        <limit lower="-3.14159" upper="3.14159" effort="100" velocity="0.005"/>
        <axis xyz="1 0 0"/>
    </joint>

    <transmission name="tran5">
        <type>transmission_interface/SimpleTransmission</type>
        <joint name="roll_up_rods_dx_up_joint">
            <hardwareInterface>EffortJointInterface</hardwareInterface>
        </joint>
        <actuator name="motor5">
            <hardwareInterface>EffortJointInterface</hardwareInterface>
            <mechanicalReduction>1</mechanicalReduction>
        </actuator>
    </transmission>
    <!-- roll_up_rods_sx_up_joint END --> 

    <!-- amr_crick_mozzo_vite_link START -->

    <link name="amr_crick_mozzo_vite_link">

        <inertial>
            <origin xyz="0 0 0" rpy="0 0 0"/>
            <mass value="0.15" />
            <inertia ixx="1.13e-11" ixy="0.0" ixz="0.0" iyy="5.28e-11" iyz="0.0" izz="5.65e-11"/>
        </inertial>
        
        <collision>
            <origin xyz="0 0 0" rpy="0 0 0"/>
            <geometry>
                <mesh filename="package://amr_crick_description/models/meshes/amr_crick_mozzo_vite.dae"/>
            </geometry>
        </collision> 

        <visual>
            <origin rpy="-1.5708 0 0" xyz="0 0 0"/>
            <geometry>
                <mesh filename="package://amr_crick_description/models/meshes/amr_crick_mozzo_vite.dae"/>
            </geometry>
             <material name="red"/>
        </visual>
    </link>

    <gazebo reference="amr_crick_mozzo_vite_link">
        <kp>1000.0</kp>
        <kd>1000.0</kd>
        <mu1>10</mu1>
        <mu2>10</mu2>
        <material>Gazebo/Grey</material>
    </gazebo>

    <!-- amr_crick_mozzo_vite_link END -->

    <!-- 6/ roll_up_rods_dx_up_joint START -->        
    <joint name="roll_down_rods_dx_up_joint" type="revolute">
        <parent link="rods_dx_up_link"/>
        <child link="amr_crick_mozzo_vite_link"/>
        <origin xyz="0 -0.078 0" rpy="0.24 0 0"/>
        <limit lower="-3.14159" upper="3.14159" effort="100" velocity="0.005"/>
        <axis xyz="1 0 0"/>
    </joint>

    <transmission name="tran6">
        <type>transmission_interface/SimpleTransmission</type>
        <joint name="roll_down_rods_dx_up_joint">
            <hardwareInterface>EffortJointInterface</hardwareInterface>
        </joint>
        <actuator name="motor6">
            <hardwareInterface>EffortJointInterface</hardwareInterface>
            <mechanicalReduction>1</mechanicalReduction>
        </actuator>
    </transmission>
    <!-- roll_up_rods_dx_up_joint END --> 

    <!-- rods_dx_down_link START -->

    <link name="rods_dx_down_link">

        <inertial>
            <origin xyz="0 0 0" rpy="0 0 0"/>
            <mass value="0.089" />
            <inertia ixx="1.42e-10" ixy="0.0" ixz="0.0" iyy="2.16e-10" iyz="0.0" izz="7.5e-11"/>
        </inertial>
       
        <collision>
            <origin xyz="0 0 0" rpy="0 0 0"/>
            <geometry>
                <mesh filename="package://amr_crick_description/models/meshes/amr_crick_rods_sx_down.dae"/>
            </geometry>
        </collision> 

        <visual>
            <origin rpy="1.5708 0 0" xyz="0 0 0"/>
            <geometry>
                <mesh filename="package://amr_crick_description/models/meshes/amr_crick_rods_sx_down.dae"/>
            </geometry>
             <material name="red"/>
        </visual>
    </link>

    <gazebo reference="rods_dx_down_link">
        <kp>1000.0</kp>
        <kd>1000.0</kd>
        <mu1>10</mu1>
        <mu2>10</mu2>
        <material>Gazebo/Grey</material>
    </gazebo>

    <!-- rods_dx_down_link END -->

    <!-- 7/ roll_up_rods_dx_down_joint START -->        
    <joint name="roll_down_rods_dx_down_joint" type="revolute">
        <parent link="amr_crick_mozzo_vite_link"/>
        <child link="rods_dx_down_link"/>
        <origin xyz="0 0 0" rpy="3.38159 0 0"/>
        <limit lower="-3.14159" upper="3.14159" effort="100" velocity="0.005"/>
        <axis xyz="1 0 0"/>
    </joint>

    <transmission name="tran7">
        <type>transmission_interface/SimpleTransmission</type>
        <joint name="roll_down_rods_dx_down_joint">
            <hardwareInterface>EffortJointInterface</hardwareInterface>
        </joint>
        <actuator name="motor7">
            <hardwareInterface>EffortJointInterface</hardwareInterface>
            <mechanicalReduction>1</mechanicalReduction>
        </actuator>
    </transmission>
    <!-- roll_up_rods_dx_down_joint END --> 

</robot>

